Workbook

Sheet Nomenclatura Campi
A1: Classe | B1: Sigla | C1: Definizione | D1: Data type | E1: Note
A2: Codice | B2: CD | C2: Identifica­ univocamente un og­get­to, una persona o altro. | D2: NUMBER/VARCHAR
A3: Descrizione | B3: DS | C3: Insieme di parole o nomi generici che descrivono qual­co­sa. | D3: VARCHAR | E3: Spesso abbinata ad un codice.
A4: Tipo | B4: TP | C4: Tipologia normalmente associata una lista di valori. | D4: VARCHAR
A5: Data | B5: DT | C5: Data del calendario. | D5: DATE (YYYY-MM-DD)
A6: Data e Orario | B6: TS | C6: Timestamp del giorno. | D6: TIMESTAMP
A7: Importo in euro | B7: EU | C7: Importo espresso in unità di euro. | D7: NUMBER | E7: Numerico con due decimali.
A8: Indicatore Flag | B8: FL | C8: Indicatore logico | D8: VARCHAR | E8: Rigorosamente a 2 valori. "S" o "N"
A9: Quantità numerica | B9: NM | C9: Valutazione di ordine quantitativo non monetario: è un numero asso­luto su cui ha senso fare dei calcoli come ad esempio delle somme. | D9: NUMBER
A10: Percentuale | B10: PC | C10: Quantità numerica riferita a 100. | D10: NUMBER
A11: Progressivo | B11: PR | C11: E’ un numero che viene generato sommando 1 all’ultimo presente. | D11: NUMBER | E11: In molti casi CD è preferibile se partecipa ad una chiave primaria. Tipico all’interno di un altro codice (es: pr_riga_ordine).
A12: Generico | B12: GN_ | C12: Utilizzato per i campi Variant. | D12: VARIANT | E12: Non dovrebbe servire in L2 ma solo su L1

Sheet Nomenclatura Frequenza Tabelle
A1: Classe | B1: Sigla/Suffisso | C1: Definizione | D1: Example | E1: Note
A2: Giornaliera | C2: Tabella con frequenza gironaliera | D2: PRATICA
A3: Settimanale | B3: _W | C3: Tabella con frequenza Settimanale | D3: PRATICA_W
A4: Mensile | B4: _M | C4: Tabella con frequenza Mensile | D4: PRATICA_M
A5: Trimestrale | B5: _T | C5: Tabella con frequenza Trimestrale | D5: PRATICA_T
A6: Quadrimestrale | B6: _Q | C6: Tabella con frequenza Quadrimestrale | D6: PRATICA_Q
A7: Semestrale | B7: _S | C7: Tabella con frequenza Semestrale | D7: PRATICA_S
A8: Annuale | B8: _Y | C8: Tabella con frequenza Annuale | D8: PRATICA_Y
A9: On Demand | B9: _O | C9: Tabella con frequenza a richiesta | D9: PRATICA_O

Sheet Nomenclatura SubjectArea Tabell
A1: Subject Area | B1: Suffisso Subject Area (COD) | C1: Definizione | D1: Example | E1: Note
A2: S.A. - ANAGRAFICA CONTROPARTE | B2: ANA_CNT | D2: L2_ANA_CNT.CONTROPARTE
A3: S.A. - ANAGRAFICA STRUTTURA COMMERCIALE | B3: ANA_COM | D3: L2_ANA_COM
A4: S.A. - HR | B4: HR | D4: L2_HR
A5: S.A. - VOICE OF CUSTOMER | B5: CNT_VOC | D5: L2_CNT_VOC
A6: S.A. - CONTATTI | B6: CNT | D6: L2_CNT
A7: S.A. - AREA RISERVATA WEB&APP | B7: DGT_ARI | D7: L2_DGT_ARI
A8: S.A. - FORM & PREVENTIVATORI | B8: DGT_FRP | D8: L2_DGT_FRP
A9: S.A. - TRACCIATURA DIGITAL | B9: DGT_TRC | D9: L2_DGT_TRC
A10: S.A. - PREVENTION | B10: GNS_PRV | D10: L2_GNS_PRV
A11: S.A. - RECOVERY | B11: GNS_RCV | D11: L2_GNS_RCV
A12: S.A. - CQS | B12: PRD_CQS | D12: L2_PRD_CQS
A13: S.A. - PAGAMENTI E CONTABILITA' | B13: PRD_PGM | D13: L2_PRD_PGM
... A31: S.A. - FINSTOCK | B31: PRD_FNS | D31: L2_PRD_FNS

Sheet Catalogo Entità
A1: Entità DM Nome | E1: "L2" -> entità L2 "LT" -> entità Layer tecnico (lookup e tabelle di conf) | M1: valorizzare S se c'è dipendenza con altre ENTITA L2, N altrimenti (NB: il campo non può essere NON valorizzato) | N1: riportare l'entità L2 con cui è presente la dipendenza (possono essere anche più di 1) | O1: valorizzare S se c'è dipendenza con altre ENTITA L2 di altre AREE di Analisi, N altrimenti (NB: il campo non può essere NON valorizzato) | P1: riportare l'AREA L2 con cui è presente la dipendenza (possono essere anche più di 1, in tal caso compilare in modo che sia chiaro il legame ENTITA COLLEGATA - AREA COLLEGATA ----->AREA COLLEGATA.ENTITA L2 COLLEGATA )
A2: Nome Entità | B2: Macro Area | C2: Subject Area | D2: ID_ENTITA | E2: TP_ENTITA | F2: DESCRIZIONE BREVE | G2: DEFINIZIONE FUNZIONALE PERIMETRO | H2: SORGENTI L1/L2 in JOIN sul campo opportuno | I2: Note | J2: ENTITA DI INTERESSE IFRS9 | K2: Regola Tecnica Perimetro (Nome tabella/e Main) | L2: Regola Tecnica Perimetro (eventuali filtri su tabella Main, chiavi o regole di join) | M2: DIPENDENZA DA ALTRE ENTITA L2 | N2: ENTITA L2 COLLEGATA | O2: DIPENDENZA DA ALTRE AREE di Analisi | P2: ALTRA AREA/SA COLLEGATA | Q2: STORICIZZAZIONE ENTITA FINALE E ARCHIVI SORGENTI | R2: PROFONDITA STORICA (a compilazione temporanea solo per area Rischi)
A3: PRATICA | B3: PRODOTTO | C3: MAIN | D3: IDL2_1 | E3: L2 | F3: Contiene le informazioni di testata delle pratiche afferenti alle procedure Consumo, Carte e CQS. Il dettaglio delle singole pratiche è disponibile nelle rispettive tabelle di procedura (Consumo, Carta e CQS), che riportano gli attributi specifici di ciascun ambito. | G3: Union delle pratiche presenti in L1.PLPRAT, L1.CRCAR, L1.QSPRA. La tabella deve essere storicizzata. | J3: N | K3: PLPRAT CRCAR QSPRA | L3: SELECT * FROM PLPRAT UNION ALL SELECT * FROM CRCAR UNION ALL SELECT * FROM QSPRA | M3: N | N3: NA | O3: N | P3: NA | Q3: S4 [L1]PLPRAT -> B2 [L1]CRCAR -> B2 [L1]QSPRA -> B2
A4: CONSUMO | B4: PRODOTTO | C4: MAIN | D4: IDL2_2 | E4: L2 | F4: Tabella che contiene il dettaglio informativo delle pratiche di tipo Consumo, integrando e specializzando le informazioni di testata presenti nella tabella delle pratiche multiprocedura. | G4: Perimetro delle pratiche provenienti dal PLPRAT | K4: PLPRAT | L4: SELECT * FROM PLPRAT | M4: N | N4: NA | O4: N | P4: NA | Q4: S4 [L1]PLPRAT -> B2
A5: CONSUMO_M | B5: PRODOTTO | C5: MAIN | F5: Tabelle delle Pratiche consumo consolidata sul fine mese. E' la versione consolidata dell'entità "CONSUMO" | G5: Perimetro delle pratiche provenienti dal PLPRAT | K5: PLPRAT | L5: SELECT * FROM PLPRAT | M5: N | N5: NA | O5: N | P5: NA | Q5: S3 [L1]PLPRAT-> B2
A6: CARTA | B6: PRODOTTO | C6: MAIN | D6: IDL2_3 | E6: L2 | F6: Tabella che contiene il dettaglio informativo delle pratiche di tipo Carta, integrando e specializzando le informazioni di testata presenti nella tabella delle pratiche multiprocedura. | G6: Perimetro delle pratiche provenienti dal CRCAR | K6: CRCAR | L6: SELECT * FROM CRCAR | M6: N | N6: NA | O6: N | P6: NA | Q6: S4 [L1]CRCAR-> B2
A7: CARTA_M | B7: PRODOTTO | C7: MAIN | F7: Tabelle delle Pratiche revolving consolidata sul fine mese. E' la versione consolidata dell'entità "CARTA" | G7: Perimetro delle pratiche provenienti dal CRCAR | K7: CRCAR | L7: SELECT * FROM CRCAR | M7: N | N7: NA | O7: N | P7: NA | Q7: S3 [L1]CRCAR-> B2
A8: CQS | B8: PRODOTTO | C8: MAIN | D8: IDL2_4 | E8: L2 | F8: Tabella che contiene il dettaglio informativo delle pratiche di tipo CQS, integrando e specializzando le informazioni di testata presenti nella tabella delle pratiche multiprocedura. | G8: Perimetro delle pratiche provenienti dal QSPRA | K8: QSPRA | L8: SELECT * FROM QSPRA | M8: N | N8: NA | O8: N | P8: NA | Q8: S4 [L1]QSPRA-> B2
A9: CQS_M | B9: PRODOTTO | C9: MAIN | F9: Tabelle delle Pratiche CCQS consolidata sul fine mese. E' la versione consolidata dell'entità "CQS" | G9: Perimetro delle pratiche provenienti dal QSPRA | K9: QSPRA | L9: SELECT * FROM QSPRA | M9: N | N9: NA | O9: N | P9: NA | Q9: S3 [L1]QSPRA-> B2
A10: VARIAZIONI_ANAGRAFICHE | B10: ANAGRAFICA​ | C10: ANAGRAFICA CONTROPARTE​ | D10: IDL2_5 | E10: L2 | F10: Tabella che contiene tutte le informazioni e le variazioni relative alle Controparti di Agos. | G10: Controparti presenti in L1.CCANALOG. | H10: CCANALOG; CCCRETCI; CCANATNA; CCANATAT; CCANATSA; CCANATPR; CCANATRE; CCANATPO | J10: Y | K10: [L1] CCANALOG | L10: SELECT AL_CODICE FROM CCANALOG | M10: N | N10: NA | O10: N | P10: NA | Q10: Cluster archivi sorgente: CCANALOG --> A1 CCCRETCI --> C CCANATNA --> C CCANATAT --> C CCANATRA --> C CCANATSA --> C CCANATPR --> C CCANATRE --> C CCANATPO --> C Storicizzazione: S1
A11: ANA_STRUTTURA_INTERNA | B11: ANAGRAFICA​ | C11: ANAGRAFICA STRUTTURA COMMERCIALE | D11: IDL2_6 | E11: L2 | F11: Tabella riassuntiva delle principali informazioni legate alla struttura interna così come è riproposta da L1. Entità necessaria per poter ricondurre la struttura interna con le entità che ragionano per filiale OCS, come provvigioni etc.. | G11: Filiali e struttura interna di riferimento proveniente dal CCANATFI | H11: JOIN1: CCANATFI.ANATFI_AREA = CCTABARE.TABARE_AREA JOIN2: CCANATFI.ANATFI_DISTRETTO = CCANATDI.ANATDI_DISTRETTO | K11: CCANATFI | L11: N | M11: N | N11: NA | O11: N | P11: NA | Q11: [L1] CCANATFI -> B2 --> S4, S3 [L1] CCANATDI -> C-->S1 [L1] CCTABARE -> C-->S1
A12: CATENE_INTERMEDIAZIONE_AGG | B12: PRODOTTO | C12: MAIN | D12: IDL2_8 | E12: L2 | F12: Tabella che associa le catene di intermediazione agggiuntive alle pratiche Agos | G12: Pratiche che hanno una catena di intermediazione aggiuntiva associata proveniente dal BAPRATINT | H12: BAPRATINT.BAINT_PUNTO_VENDITA = CCANAIPV. IPV_CODICE | K12: BAPRATINT (L1) | L12: SELECT * FROM BAPRATINT WHERE BAPRATINT.BAINT_PROGRESSIVO >=1 | M12: N | N12: NA | O12: N | P12: NA | Q12: S4 [L1] BAPRATINT -> B2
A13: SALDO_GESTIONALE_M | B13: RISCHI E ADEMPIMENTI​ | C13: SALDI​ | D13: IDL2_9 | E13: L2 | F13: Tabella dei Saldi a fine mese (End Of Month) mostra la vista gestionale | G13: Pratiche in L1.OXDRFPRA | H13: OXDRFPRA OXIAFCOMPE | I13: Dati Storico -> OP 429 + OP 516 | J13: Y | K13: SELECT * FROM OXDRFPRA | L13: SELECT * FROM OXDRFPRA WHERE DRPRA_DATA_ESTRAZIONE=LAST_DAY(DATEADD('month', -1, CURRENT_DATE())) | M13: N | N13: N | O13: N | P13: NA | Q13: S3
A14: SALDO_CONTABILE_M | B14: RISCHI E ADEMPIMENTI​ | C14: SALDI​ | D14: IDL2_147 | E14: L2 | F14: Tabella dei Saldi a fine mese (End Of Month) mostra la vista contabile | G14: Pratiche in L1.OXDRFPRA | H14: OXDRFPRA OXIAFCOMPE | J14: Y | K14: SELECT * FROM OXDRFPRA | L14: SELECT * FROM OXDRFPRA WHERE DRPRA_DATA_ESTRAZIONE=LAST_DAY(DATEADD('month', -1, CURRENT_DATE())) | M14: N | N14: N | O14: N | P14: NA | Q14: S3
A15: RIMBORSI | B15: PRODOTTO | C15: PAGAMENTI E CONTABILITA​ | D15: IDL2_10 | E15: L2 | F15: Tabella dei Rimborsi | G15: Elenco dei Rimborsi avvenuti sulle pratiche presenti in L1.PLPRAT, L1.CRCAR, L1.QSPRA | I15: DRAFT, in attesa sviluppi OCS. Il perimetro di questa entità dovrebbe essere individuato a partire da un report prodotto da OCS riguardante, nello specifico, i rimborsi. | J15: N
A16: SCARTI | B16: PRODOTTO | C16: PAGAMENTI E CONTABILITA​ | D16: IDL2_11 | E16: L2 | F16: Tabella degli Scarti: Rimborsi che non vengono effettuati | G16: Elenco degli Scarti sulle pratiche presenti in L1.PLPRAT, L1.CRCAR, L1.QSPRA | I16: DRAFT, in attesa sviluppi OCS. Il perimetro di questa entità dovrebbe essere individuato a partire da un report prodotto da OCS riguardante, nello specifico, gli scarti. | J16: N
A17: DOMINIO_SCARTO | B17: PRODOTTO | C17: PAGAMENTI E CONTABILITA​ | D17: IDL2_12 | E17: L2 | F17: Tabella con tutte le tipologie di Motivo Scarto con codice, descrizione e gerarchia dello scarto. | I17: DRAFT, in attesa sviluppi OCS | J17: N
A18: PRATICA_M | B18: PRODOTTO | C18: MAIN | D18: IDL2_15 | E18: L2 | F18: Tabelle delle Pratiche consolidata sul fine mese. E' la versione consolidata dell'entità "PRATICA" | G18: Union delle pratiche presenti in L1.PLPRAT, L1.CRCAR, L1.QSPRA. La tabella deve essere storicizzata. | J18: Y | K18: PLPRAT CRCAR QSPRA | L18: SELECT * FROM PLPRAT UNION ALL SELECT * FROM CRCAR SELECT * FROM QSPRA | M18: N | N18: NA | O18: N | P18: NA | Q18: S3 [L1]PLPRAT -> B2 [L1]CRCAR -> B2 [L1]QSPRA -> B2
A19: SVALUTAZIONI_M | B19: RISCHI E ADEMPIMENTI​ | C19: RISCHI​ | D19: IDL2_16 | E19: L2 | F19: Tabelle delle Pratiche in svalutazioni con annessi importi sulle dinamiche (per tutte le pratiche, comprese casistiche fuori bilancio o enti finanziari) | G19: Lista delle Pratiche oggetto di svalutazione nel mese M (In attesa mappatura OCS). La tabella contiene le pratiche a livello originator, con eventuale integrazione delle componenti cartolarizzate, schiacciando gli importi quando entrambe sono presenti. | J19: Y | K19: SVESFCRSC | L19: SELECT SVCRSC_PRATICA, SVCRSC_PROCEDURA, SVCRSC_ANNO_ESTRAZIONE, SVCRSC_MESE_ESTRAZIONE FROM SVESFCRSC | M19: N | N19: NA | O19: N | P19: NA | Q19: [L1] SVESFCRSC --> B1 --> S1 | R19: chiedere a migrazione: finance (almeno tutti i dicembre/fine anno disponibili - dati di fine anno precedente)
A20: FORBEARANCE_M | B20: RISCHI E ADEMPIMENTI​ | C20: RISCHI​ | D20: IDL2_17 | E20: L2 | F20: Tabella che registra informazioni sulle pratiche in forbearance | G20: Lista delle Pratiche entrate, rimaste o uscite dallo stato di forbearance nel mese M (In attesa mappatura OCS) | J20: Y | K20: OXDRFPRA | L20: SELECT * FROM OXDRFPRA | M20: N | N20: NA | O20: N | P20: NA | Q20: [L1] OXDRFPRA --> A1 --> S3 | R20: tutto quello che c'è
A21: INCASSI_BOLLETTINI | B21: PRODOTTO | C21: PAGAMENTI E CONTABILITA​ | D21: IDL2_18 | E21: L2 | F21: Tabella che registra gli incassi tramite Bollettino | G21: Lista dei bollettini incassati: L1.CRCCPTES, L1.CRCCPDET, L1.BACCPDET, L1.BACCPTES | H21: CAINFBPDT, CGEVNT | J21: N | K21: [L1]BACCPDET | M21: N | N21: NA | O21: N | P21: NA | Q21: [L1]BACCPDET->A1
A22: INCASSI_CAMBIALI | B22: PRODOTTO | C22: PAGAMENTI E CONTABILITA​ | D22: IDL2_19 | E22: L2 | F22: Tabella che registra gli incassi tramite Cambiale (si ritengono incluse anche cambiali future) | G22: Lista dei bollettini cambiali: GAEFARC + archivi in sviluppo | H22: EFEXFINCDE? | J22: N/Y approfondimenti in corso | K22: [L1]GAEFARC | M22: N | N22: NA | O22: N | P22: NA | Q22: [L1]GAEFARC->A2
A23: INCASSI_BONIFICI | B23: PRODOTTO | C23: PAGAMENTI E CONTABILITA​ | D23: IDL2_20 | E23: L2 | F23: Tabella che registra gli incassi tramite Bonifico | G23: LIsta dei bonifici: CCBONISET | I23: Manca campo sorgente per CD_TERZO_ORDINANTE | J23: N | K23: [L1]CCBONISET | M23: N | N23: NA | O23: N | P23: NA | Q23: [L1]CCBONISET->A1
A24: INCASSI_SDD | B24: PRODOTTO | C24: PAGAMENTI E CONTABILITA​ | D24: IDL2_21 | E24: L2 | F24: Tabella che registra gli incassi tramite SDD | G24: Lista degli SDD: CCCASTE | H24: CCNEWABI | J24: N | K24: [L1]CCNEWABI | M24: N | N24: NA | O24: N | P24: NA | Q24: [L1]CCCASTE->A2 [L1] CCNEWABI ->C
A25: MANDATI_INCASSI_SDD | B25: PRODOTTO | C25: PAGAMENTI E CONTABILITA​ | D25: IDL2_22 | E25: L2 | F25: Tabella che registra i mandati SDD e RID | G25: Lista dei mandati SDD: ICMAFMAN | H25: BNPTCUC_CODICE_SIA | J25: N | K25: [L1]ICMAFMAN | M25: N | N25: NA | O25: N | P25: NA | Q25: [L1]CMAFMAN->A2
A26: INCASSI | B26: PRODOTTO | C26: PAGAMENTI E CONTABILITA​ | D26: IDL2_23 | E26: L2 | F26: Tabella degli incassi che registra movimenti in ingresso effettuati con qualsiasi metodologia di pagamento | G26: Lista degli incassi cross sulla tipologia di pagamento: Aspettiamo approfondimento con OCS | J26: Y
A27: INCASSI_TESTATA | B27: PRODOTTO | C27: PAGAMENTI E CONTABILITA​ | D27: IDL_159 | E27: L2 | F27: Tabella degli incassi che registra informazioni generiche sui movimenti in ingresso | G27: OXINFREPT | I27: Manca campo sorgente per DT_INIZIO_VALIDITà e DT_FINE_VALIDITà | J27: Y | K27: [l1] OXINFREPT | M27: S | N27: INCASSI_DETTAGLIO | O27: N | P27: NA | Q27: [L1]OXINFREPT->A2
A28: INCASSI_DETTAGLIO | B28: PRODOTTO | C28: PAGAMENTI E CONTABILITA​ | D28: IDL_160 | E28: L2 | F28: Tabella degli incassi che registra informazioni specifiche sui movimenti in ingresso | G28: OXINFREPD | I28: Manca campo sorgente per DT_INIZIO_VALIDITà e DT_FINE_VALIDITà | J28: Y | K28: [l1] OXINFREPD | M28: S | N28: INCASSI_TESTATA | O28: N | P28: NA | Q28: [l1] OXINFREPD -> A2
A29: PAGAMENTI | B29: PRODOTTO | C29: PAGAMENTI E CONTABILITA​ | D29: IDL2_24 | E29: L2 | F29: Tabella dei pagamenti che registra movimenti in uscita effettuati con qualsiasi metodologia di pagamento | G29: Lista dei pagementi cross sulla tipologia di pagamento: CCBONWK + archivi in sviluppo per Vidaut | J29: N
A30: PAGAMENTI_TESTATA | B30: PRODOTTO | C30: PAGAMENTI E CONTABILITA​ | D30: IDL_161 | E30: L2 | F30: Tabella dei pagamenti che registra informazioni generiche sui movimenti in uscita | G30: CCRIMBO | J30: N | M30: S | N30: PAGAMENTI_TESTATA, PAGAMENTI_VIDAUT | P30: NA | Q30: ?
A31: PAGAMENTI_BONIFCI | B31: PRODOTTO | C31: PAGAMENTI E CONTABILITA​ | D31: IDL_162 | E31: L2 | F31: Tabella dei pagamenti che registra movimenti in uscita di tipologia bonifico | G31: CCBONWK | I31: Campo EU_COMMISSIONI in validazione per Campioni | J31: N | K31: [L1] CCBONWK | M31: S | N31: PAGAMENTI_TESTATA | O31: N | P31: NA | Q31: [L1] CCBONWK->A2
A32: PAGAMENTI_VIDAUT | B32: PRODOTTO | C32: PAGAMENTI E CONTABILITA​ | D32: IDL_163 | E32: L2 | F32: Tabella dei pagamenti che registra movimenti in uscita di tipologia vidaut
A33: LEGAME_CARTOLARIZZAZIONI | B33: RISCHI E ADEMPIMENTI​ | C33: RISCHI​ | D33: IDL2_26 | E33: L2 | F33: Tabella di legame per la pratica cartolarizzata e la pratica OCS. Utilizzata per centralizzare le regole per le pratiche cartolarizzate | G33: Lista delle pratiche cartolarizzate associate alle pratiche originali | K33: OXDRFPRA | L33: SELECT * FROM OXDRFPRA | M33: N | N33: NA | O33: N | P33: NA | Q33: [L1] OXDRFPRA --> A1 --> S3 | R33: --
A34: STATO_CREDITIZIO_M | B34: RISCHI E ADEMPIMENTI​ | C34: RISCHI​ | D34: IDL2_27 | E34: L2 | F34: Tabella che registra le variazioni sulla qualità creditizia delle pratiche. Include informazioni sulla qualità creditizia, stage e default eba | G34: Lista delle pratiche per le quali è valorizzato lo stato creditizio | J34: Y | K34: OXDRFPRA | L34: SELECT * FROM OXDRFPRA | M34: Y | N34: LEGAME_PRAT_CONTR | O34: Y | P34: ANAGRAFICA CONTROPARTE​ | Q34: [L1] OXDRFPRA --> A1 --> S3 | R34: --
A35: GESTIONE_TRUFFE | B35: SCORING & DATA ENRICHMENT​ | C35: ANTIFRODE​ | D35: IDL2_28 | E35: L2 | F35: Tabella che registra la marchiatura delle pratiche come truffa | G35: Pratiche per cui è stata registrata una truffa | I35: In attesa di mappatura da parte di OCS -> OP Jira di riferimento : AGXDMW1-394 Valutare di cambiare il nome per evitare la ridondanza e fuorvianza di "PRATICHE" nel nome. | J35: Y | K35: OXTRFTRU | L35: SELECT *FROM OXTRFTRU | M35: N | N35: N | O35: N | P35: NA | Q35: A2--> S2
A36: DOC_ISTRUTTORIA | B36: PRODOTTO | C36: ONBOARDING​ | D36: IDL2_29 | E36: L2 | F36: Tabella che associa alle pratiche i documenti richiesti in checklist documentale e riporta lo stato riguardo il rientro della suddetta documentazione. Oltre alle checklist documentali per l'istruttoria di una pratica, sono riportate in questa tabella anche le checklist documentali relative al convenzionamento di un partner. | G36: Perimetro dati coincidente con OXDOFD | H36: OXDOFT OXDOFTPR OXDOFTCV OXTBFDOC OXDOFTBST OXDOFTSEDO PLTBFDOCR CADOFTDO QSTABDRI OXDOFTSI | I36: In attesa di mappatura da parte di OCS -> OP Jira di riferimento : AGXDMW1-394 | J36: N | K36: OXDOFD | L36: Select * from OXDOFD | M36: NA | N36: NA | O36: NA | P36: NA | Q36: S4 Le tabelle sono tutte delle C ma le attualizziamo, prendiamo solo la finestra valida MAIN -> OXDOFD OXDOFT OXDOFTPR OXDOFTCV OXTBFDOC OXDOFTBST OXDOFTSEDO PLTBFDOCR CADOFTDO QSTABDRI OXDOFTSI
A37: ANA_INTERMEDIARI_BASE | B37: ANAGRAFICA​ | C37: ANAGRAFICA STRUTTURA COMMERCIALE | D37: IDL2_31 | E37: L2 | F37: Tabella anagrafica base riassuntiva delle principali informazioni legate alle catene di intermediaizone e intermediari. | J37: S | K37: CCANAIAG | L37: N | M37: N | N37: NA | O37: N | P37: NA | Q37: [L1] CCANAGR -> B1 --> S1 [L1] CCANAIAG -> B1 [L1] CCANAICV -> B1 [L1] CCANAIPV -> B1 [L1] CCANAISA -> B1 [L1] CCANAIVE -> B1
A38: SERVIZI_ASSICURATIVI_SINISTRI | B38: PRODOTTO | C38: ASSICURAZIONI​ | D38: IDL2_32 | E38: L2 | F38: Tabella che registra l'avvenimento dei sinistri sui servizi | I38: In attesa di mappatura da parte di OCS -> OP Jira di riferimento : AGXDMW1-394 | J38: N | M38: N | N38: N | O38: N | P38: N | Q38: OP. Entità ancora in sviluppo da parte di OCS
A39: CARTE_LIMITAZIONI_OPERATIVITA | B39: PRODOTTO | C39: CARTE​ | D39: IDL2_14 | E39: L2 | F39: Proprietà dei blocchi delle carte. Contiene il dettaglio dei blocchi. I dettagli sono raggiungibili facendo JOIN tra BLOCCHI_CARTE che contiene riferimento (FK) a questa tabella. | K39: CRCARBLO | L39: CRCARBLO | M39: Y | N39: VARIAZIONI_STATO_PRAT | Q39: [L1] CRCARBLO --> A2 [L2] VARIAZIONI_STATO_PRAT
A40: CARTE_UTILIZZI | B40: PRODOTTO | C40: CARTE​ | D40: IDL2_33 | E40: L2 | F40: Entità core degli utilizzi delle carte, dove verranno censite solamente le informazioni principali degli avvenuti utilizzi della carta. Le transazioni approvate. Le informazioni del POS di fine giornata provenienti dai circuiti internazionali. Le informazioni delle eventuali promozioni legate all’utilizzo della carta | I40: In attesa di mappatura da parte di OCS -> OP Jira di riferimento : AGXDMW1-394 | J40: Y/N da approfondire se effettivamente la usiamo in senso attivo | K40: CRVOUF | L40: CRVOUF | M40: N | N40: N | O40: N | P40: N | Q40: CRVOUF --> C --> S1 CRVOUA --> C --> S1 CRINSTANT --> C --> S1 CRCROSVOU --> C --> S1 CRCAR ROTBFCAU -> C --> S1 CRTABCAM --> C --> S1 CRCAMP --> A2 --> S2 PSINTACQ --> A2 --> S2 PSSICCOD --> C --> S1 CRAUT --> C --> S1
...

Sheet SOCIODEMO_OLD
D1: Dominio del campo STATO: "Validato per processo X": campi che abbiamo validato e non ci aspettiamo di toccare più (nessun OP legato) "In Validazione per processo X": tutti gli altri stati N.B. è possibile inserire "Validato per processo generico"/ "In Validazione per processo generico" se il campo è emerso senza un legame con un processo specifico | E1: CONSUMO | H1: CARTE
A2: CATEGORIA CAMPO | B2: NOME CAMPO | C2: DESCRIZIONE | D2: STATO (CAMPO VALIDATO / IN VALIDAZIONE) | E2: SORGENTE TABELLA OCS L1 | F2: SORGENTE CAMPI OCS L1 | G2: REGOLA FUNZIONALE | H2: SORGENTE TABELLA OCS L1 | I2: SORGENTE CAMPI OCS L1 | J2: REGOLA FUNZIONALE | K2: NOTE
A3: Identificativo Pratica | B3: CD_PRATICA | C3: Codice Pratica | D3: Validato per Campioni, Monitoraggio Accettazione, validato per IFRS9 | K3: + OP 556 impatti IFRS9
B4: TP_PROCEDURA | C4: Tipologia procedura | D4: Validato per Campioni, Monitoraggio Accettazione, validato per IFRS9 | K4: + OP 556 impatti IFRS9
A5: Tempo | B5: DT_OSSERVAZIONE | C5: Periodo Osservazione | D5: Validato per Campioni, Monitoraggio Accettazione, validato per IFRS9 | K5: + OP 556 impatti IFRS9
A6: Identificativo Controparte | B6: CD_CONTROPARTE | C6: Codice Controparte | D6: Validato per Campioni, Monitoraggio Accettazione, validato per IFRS9 | K6: + OP 556 impatti IFRS9
B7: TP_RAPPORTO | C7: Tipologia Rapporto | D7: Validato per Campioni, Monitoraggio Accettazione, validato per IFRS9 | K7: + OP 556 impatti IFRS9
B8: TP_CONTROPARTE | C8: Tipologia Controparte | D8: Validato per Campioni, Monitoraggio Accettazione, validato per IFRS9 | K8: + OP 556 impatti IFRS9
A9: Cliente | B9: CD_CLIENTE_CTC | C9: Codice CTC Cliente | D9: Validato per Campioni, Monitoraggio Accettazione, validato per IFRS9 | K9: + OP 556 impatti IFRS9
B10: CD_COOBLIGATO_CTC | C10: Codice CTC Coobligato | D10: Validato per Campioni, Monitoraggio Accettazione, validato per IFRS9 | K10: + OP 556 impatti IFRS9
B11: CD_CLIENTE | C11: Codice Cliente Agos | D11: Validato per Campioni, Monitoraggio Accettazione, validato per IFRS9 | K11: + OP 556 impatti IFRS9
B12: CD_COOBLIGATO | C12: Codice Coobligato Agos | D12: Validato per Campioni, Monitoraggio Accettazione, validato per IFRS9 | K12: + OP 556 impatti IFRS9
A13: Date | B13: DT_CARIC_ULT_PP_REMOTO | C13: Data di caricamento ultima pratica di prestito personale dell’ambiente remoto | D13: Validato per Campioni, Monitoraggio Accettazione, validato per IFRS9 | K13: + OP 556 impatti IFRS9
B14: DT_ULTIMA_MORA | C14: Data ultima mora | D14: Validato per Campioni, Monitoraggio Accettazione, validato per IFRS9 | K14: + OP 556 impatti IFRS9
B15: DT_PRIMO_UTILIZZO | C15: Data di primo utilizzo | D15: Validato per Campioni, Monitoraggio Accettazione, validato per IFRS9 | E15: BAPRATPD | F15: BAPRATPD.BAP_DATA_U | H15: BAPRATPD | I15: BAPRATPD.BAP_DATA_U
B16: DT_INIZIO_RAPP_CLIE | C16: Data inizio rapporto cliente | D16: Validato per Campioni, Monitoraggio Accettazione, validato per IFRS9 | K16: + OP 556 impatti IFRS9
B17: DT_APERTURA_PRIMA_PRATICA | C17: Data apertura prima pratica | D17: In validazione per Monitoraggio Accettazione, validato per IFRS9 | K17: + OP 556 impatti IFRS9
A18: Dati Anagrafica (generici) | B18: CD_SESSO_CLIENTE | C18: Codice Sesso Cliente | D18: Validato per Campioni, Monitoraggio Accettazione, validato per IFRS9 | K18: + OP 556 impatti IFRS9
B19: CD_CITTADINANZA | C19: Codice cittadinanza cliente | D19: Validato per Campioni, Monitoraggio Accettazione, validato per IFRS9 | K19: + OP 556 impatti IFRS9
B20: NM_FAMILIARI | C20: Numero familiari | D20: Validato per Campioni, Monitoraggio Accettazione, validato per IFRS9 | K20: + OP 556 impatti IFRS9
B21: CD_STATO_CIVILE | C21: Codice stato civile cliente | D21: Validato per Campioni, Monitoraggio Accettazione, validato per IFRS9 | K21: + OP 556 impatti IFRS9
B22: CD_STATO_CIVILE_COOBLIGATO | C22: Codice Stato Civile Coobbligato | D22: Validato per Campioni, Monitoraggio Accettazione, validato per IFRS9 | K22: + OP 556 impatti IFRS9
B23: CD_CONIUGE_GARANTE | C23: Flag Coniuge garante | D23: Validato per Campioni, Monitoraggio Accettazione, validato per IFRS9 | K23: + OP 556 impatti IFRS9
B24: CD_FORMA_GIURIDICA | C24: Codice Forma Giuridica | D24: Validato per Campioni, Monitoraggio Accettazione, validato per IFRS9 | E24: OXANFVAN | F24: OXANFVAN.AC_FORMA_GIURIDICA | H24: OXANFVAN | I24: OXANFVAN.AC_FORMA_GIURIDICA
B25: DT_NASCITA_CLIENTE | C25: Data di nascita cliente | D25: Validato per Campioni, Monitoraggio Accettazione, validato per IFRS9 | K25: + OP 556 impatti IFRS9
B26: CD_PROVINCIA_NASCITA | C26: Codice Provincia Nascita cliente | D26: Validato per Campioni, Monitoraggio Accettazione, validato per IFRS9 | K26: + OP 556 impatti IFRS9
B27: CD_QUALITA_CLIE | C27: Codice Qualità Cliente | D27: Validato per Campioni, Monitoraggio Accettazione, validato per IFRS9 | K27: + OP 556 impatti IFRS9
B28: CD_QUALITA_CONV | C28: Codice Qualità Convenzionato | D28: Validato per Campioni, Monitoraggio Accettazione, validato per IFRS9 | K28: + OP 556 impatti IFRS9
B29: CD_TIPO_AZIENDA_CLI | C29: Tipo azienda cliente | D29: Validato per Campioni, Monitoraggio Accettazione, validato per IFRS9 | K29: + OP 556 impatti IFRS9
B30: DT_INIZIO_RAPP_BANCA | C30: Data inizio rapporto banca | D30: Validato per Campioni, Monitoraggio Accettazione, validato per IFRS9 | K30: + OP 556 impatti IFRS9
B31: TP_PRATICA_INTERNET | C31: Tipo Pratica Internet | D31: Validato per Campioni, Monitoraggio Accettazione, validato per IFRS9 | K31: + OP 556 impatti IFRS9
B32: NM_PRATICHE_CLIENTE | C32: Pratiche precedentemente liquidate per lo stesso cliente | D32: In validazione per Monitoraggio Accettazione, validato per IFRS9 | K32: + OP 556 impatti IFRS9
A33: Dati Anagrafica (attività) | B33: TP_ATTIVITA | C33: Tipo attività, lavoro del cliente: Autonomo, dipendente, Pensionato | D33: Validato per No Start, Monitoraggio Accettazione, validato per IFRS9 | E33: BAPRATCT | F33: BAPCT_QUALIFICA | H33: BAPRATCT | I33: BAPCT_QUALIFICA
B34: CD_SETT_ATTIVITA_COOBLIGATO | C34: settore attività coobligato | D34: Validato per Campioni, Monitoraggio Accettazione, validato per IFRS9 | K34: + OP 556 impatti IFRS9
B35: CD_SETT_ATTIVITA_CLIENTE | C35: settore attività cliente | D35: Validato per Campioni, Monitoraggio Accettazione, validato per IFRS9 | K35: + OP 556 impatti IFRS9
B36: CD_OCCUPAZIONE | C36: Codice Occupazione | D36: Validato per Campioni, Monitoraggio Accettazione, validato per IFRS9 | K36: + OP 556 impatti IFRS9
B37: DT_INIZIO_OCCUP | C37: data occupazione cliente | D37: Validato per Campioni, Monitoraggio Accettazione, validato per IFRS9 | K37: + OP 556 impatti IFRS9
B38: TP_CONTRATTO_LAVORO | C38: tipo contratto: tempo det/indet | D38: Validato per Campioni, Monitoraggio Accettazione, validato per IFRS9 | E38: BAPRATCT | F38: BAPCT_TIPO_CONTRATTO
B39: NM_MESI_DURATA | C39: Durata contratto lavoro | D39: Validato per Campioni, Monitoraggio Accettazione, validato per IFRS9 | K39: + OP 556 impatti IFRS9
B40: NM_MENSILITA_CLIENTE | C40: Numero mensilità cliente | D40: In validazione per Monitoraggio Accettazione, validato per IFRS9 | E40: BAPRATCT | F40: BAPCT_NUM_MENSILITA | H40: BAPRATCT | I40: BAPCT_NUM_MENSILITA
...

Sheet SOCIODEMO_SCORE_OLD
B1: ORE | D1: Dominio del campo STATO: "Validato per processo X": campi che abbiamo validato e non ci aspettiamo di toccare più (nessun OP legato) "In Validazione per processo X": tutti gli altri stati N.B. è possibile inserire "Validato per processo generico"/ "In Validazione per processo generico" se il campo è emerso senza un legame con un processo specifico | E1: CONSUMO | H1: CARTE
A2: CATEGORIA CAMPO | B2: NOME CAMPO | C2: DESCRIZIONE | D2: STATO (CAMPO VALIDATO / IN VALIDAZIONE) | E2: SORGENTE TABELLA OCS L1 | F2: SORGENTE CAMPI OCS L1 | G2: REGOLA FUNZIONALE | H2: SORGENTE TABELLA OCS L1 | I2: SORGENTE CAMPI OCS L1 | J2: REGOLA FUNZIONALE | K2: NOTE
A3: Identificativo Pratica | B3: CD_PRATICA | C3: Codice Pratica | D3: In Validazione per Campioni, Validato per IFRS9 | K3: + OP 556 impatti IFRS9
B4: TP_PROCEDURA | C4: Tipologia procedura | D4: In Validazione per Campioni, Validato per IFRS9 | K4: + OP 556 impatti IFRS9
A5: Tempo | B5: DT_OSSERVAZIONE | C5: Periodo Osservazione | D5: In Validazione per Campioni, Validato per IFRS9 | K5: + OP 556 impatti IFRS9
A6: Identificativo Controparte | B6: CD_CONTROPARTE | C6: Codice Controparte | D6: In Validazione per Campioni, Validato per IFRS9 | K6: + OP 556 impatti IFRS9
B7: TP_RAPPORTO | C7: Tipologia Rapporto | D7: In Validazione per Campioni, Validato per IFRS9 | K7: + OP 556 impatti IFRS9
B8: TP_CONTROPARTE | C8: Tipologia Controparte | D8: In Validazione per Campioni, Validato per IFRS9 | K8: + OP 556 impatti IFRS9
A9: Cliente | B9: CD_CLIENTE_CTC | C9: Codice CTC Cliente | D9: In Validazione per Campioni, Validato per IFRS9 | K9: + OP 556 impatti IFRS9
B10: CD_COOBLIGATO_CTC | C10: Codice CTC Coobligato | D10: In Validazione per Campioni, Validato per IFRS9 | K10: + OP 556 impatti IFRS9
B11: CD_CLIENTE | C11: Codice Cliente Agos | D11: In Validazione per Campioni, Validato per IFRS9 | K11: + OP 556 impatti IFRS9
B12: CD_COOBLIGATO | C12: Codice Coobligato Agos | D12: In Validazione per Campioni, Validato per IFRS9 | K12: + OP 556 impatti IFRS9
A13: Date | B13: DT_CARIC_ULT_PP_REMOTO | C13: Data di caricamento ultima pratica di prestito personale dell’ambiente remoto. Rappresenta l'informazione generata in istruttoria e non viene modificata in postvendita | D13: In Validazione per Campioni, Validato per IFRS9 | K13: + OP 556 impatti IFRS9
B14: DT_ULTIMA_MORA | C14: Data ultima mora. Rappresenta l'informazione generata in istruttoria e non viene modificata in postvendita | D14: In Validazione per Campioni, Validato per IFRS9 | K14: + OP 556 impatti IFRS9
B15: DT_PRIMO_UTILIZZO | C15: Data di primo utilizzo. Rappresenta l'informazione generata in istruttoria e non viene modificata in postvendita | D15: In Validazione per Campioni, Validato per IFRS9 | E15: BAPRATPD | F15: BAPRATPD.BAP_DATA_U | H15: BAPRATPD | I15: BAPRATPD.BAP_DATA_U
B16: DT_INIZIO_RAPP_CLIE | C16: Data inizio rapporto cliente. Rappresenta l'informazione generata in istruttoria e non viene modificata in postvendita | D16: In Validazione per Campioni, Validato per IFRS9 | K16: + OP 556 impatti IFRS9
B17: DT_APERTURA_PRIMA_PRATICA | C17: Data apertura prima pratica. Rappresenta l'informazione generata in istruttoria e non viene modificata in postvendita | D17: In validazione per Monitoraggio Accettazione, Validato per IFRS9 | K17: Legato a sviluppi che si faranno tra Febbraio e Giugno 26 + OP 556 impatti IFRS9
A18: Dati Anagrafica (generici) | B18: CD_SESSO_CLIENTE | C18: Codice Sesso Cliente. Rappresenta l'informazione generata in istruttoria e non viene modificata in postvendita | D18: In Validazione per Campioni, Validato per IFRS9 | K18: + OP 556 impatti IFRS9
B19: CD_CITTADINANZA | C19: Codice cittadinanza cliente. Rappresenta l'informazione generata in istruttoria e non viene modificata in postvendita | D19: In Validazione per Campioni, Monitoraggio Accettazione, Validato per IFRS9 | K19: + OP 556 impatti IFRS9
B20: NM_FAMILIARI | C20: Numero familiari. Rappresenta l'informazione generata in istruttoria e non viene modificata in postvendita | D20: In Validazione per Campioni, Validato per IFRS9 | K20: + OP 556 impatti IFRS9
B21: CD_STATO_CIVILE | C21: Codice stato civile cliente. Rappresenta l'informazione generata in istruttoria e non viene modificata in postvendita | D21: In Validazione per Campioni, Monitoraggio Accettazione, Validato per IFRS9 | K21: + OP 556 impatti IFRS9
B22: CD_STATO_CIVILE_COOBLIGATO | C22: Codice Stato Civile Coobbligato. Rappresenta l'informazione generata in istruttoria e non viene modificata in postvendita | D22: In Validazione per Campioni, Validato per IFRS9 | K22: + OP 556 impatti IFRS9
B23: CD_CONIUGE_GARANTE | C23: Flag Coniuge garante. Rappresenta l'informazione generata in istruttoria e non viene modificata in postvendita | D23: In Validazione per Campioni, Validato per IFRS9 | K23: + OP 556 impatti IFRS9
B24: CD_FORMA_GIURIDICA | C24: Codice Forma Giuridica. Rappresenta l'informazione generata in istruttoria e non viene modificata in postvendita | D24: In Validazione per Campioni, Validato per IFRS9 | E24: OXANFVAN | F24: OXANFVAN.AC_FORMA_GIURIDICA | H24: OXANFVAN | I24: OXANFVAN.AC_FORMA_GIURIDICA
B25: DT_NASCITA_CLIENTE | C25: Data di nascita cliente. Rappresenta l'informazione generata in istruttoria e non viene modificata in postvendita | D25: In Validazione per Campioni, Monitoraggio Accettazione, Validato per IFRS9 | K25: + OP 556 impatti IFRS9
B26: CD_PROVINCIA_NASCITA | C26: Codice Provincia Nascita cliente. Rappresenta l'informazione generata in istruttoria e non viene modificata in postvendita | D26: In Validazione per Campioni, Validato per IFRS9 | K26: + OP 556 impatti IFRS9
B27: CD_QUALITA_CLIE | C27: Codice Qualità Cliente. Rappresenta l'informazione generata in istruttoria e non viene modificata in postvendita | D27: In Validazione per Campioni, Monitoraggio Accettazione, Validato per IFRS9 | K27: + OP 556 impatti IFRS9
B28: CD_QUALITA_CONV | C28: Codice Qualità Convenzionato. Rappresenta l'informazione generata in istruttoria e non viene modificata in postvendita | D28: In Validazione per Campioni, Validato per IFRS9 | K28: + OP 556 impatti IFRS9
B29: CD_TIPO_AZIENDA_CLI | C29: Tipo azienda cliente. Rappresenta l'informazione generata in istruttoria e non viene modificata in postvendita | D29: In Validazione per Campioni, Validato per IFRS9 | K29: + OP 556 impatti IFRS9
B30: DT_INIZIO_RAPP_BANCA | C30: Data inizio rapporto banca. Rappresenta l'informazione generata in istruttoria e non viene modificata in postvendita | D30: In Validazione per Campioni, Validato per IFRS9 | K30: + OP 556 impatti IFRS9
B31: TP_PRATICA_INTERNET | C31: Tipo Pratica Internet. Rappresenta l'informazione generata in istruttoria e non viene modificata in postvendita | D31: In Validazione per Campioni, Validato per IFRS9 | K31: + OP 556 impatti IFRS9
B32: NM_PRATICHE_CLIENTE | C32: Pratiche precedentemente liquidate per lo stesso cliente. Rappresenta l'informazione generata in istruttoria e non viene modificata in postvendita | D32: In validazione per Monitoraggio Accettazione, Validato per IFRS9 | K32: Legato a sviluppi che si faranno tra Febbraio e Giugno 26 + O + OP 556 impatti IFRS9
A33: Dati Anagrafica (attività) | B33: TP_ATTIVITA | C33: Tipo attività, lavoro del cliente: Autonomo, dipendente, Pensionato. Rappresenta l'informazione generata in istruttoria e non viene modificata in postvendita | D33: Validato per No Start, Validato per IFRS9 | E33: BAPRATCT | F33: BAPCT_QUALIFICA | H33: BAPRATCT | I33: BAPCT_QUALIFICA
B34: TP_AMBITO_LAVORATIVO | D34: In Validazione per Vendite
B35: CD_SETT_ATTIVITA_COOBLIGATO | C35: settore attività coobligato. Rappresenta l'informazione generata in istruttoria e non viene modificata in postvendita | D35: In Validazione per Campioni, Monitoraggio Accettazione, Validato per IFRS9 | K35: + OP 556 impatti IFRS9
B36: CD_SETT_ATTIVITA_CLIENTE | C36: settore attività cliente. Rappresenta l'informazione generata in istruttoria e non viene modificata in postvendita | D36: In Validazione per Campioni, Monitoraggio Accettazione, Validato per IFRS9 | K36: + OP 556 impatti IFRS9
B37: CD_OCCUPAZIONE | C37: Codice Occupazione. Rappresenta l'informazione generata in istruttoria e non viene modificata in postvendita | D37: In Validazione per Campioni, Monitoraggio Accettazione, Validato per IFRS9 | K37: P 556 impatti IFRS9
B38: DT_INIZIO_OCCUP | C38: data occupazione cliente. Rappresenta l'informazione generata in istruttoria e non viene modificata in postvendita | D38: In Validazione per Campioni, Monitoraggio Accettazione, Validato per IFRS9 | K38: + OP 556 impatti IFRS9
B39: TP_CONTRATTO_LAVORO | C39: tipo contratto: tempo det/indet. Rappresenta l'informazione generata in istruttoria e non viene modificata in postvendita | D39: In Validazione per Campioni, Monitoraggio Accettazione, Validato per IFRS9 | E39: BAPRATCT | F39: BAPCT_TIPO_CONTRATTO
B40: NM_MESI_DURATA | C40: Durata contratto lavoro. Rappresenta l'informazione generata in istruttoria e non viene modificata in postvendita | D40: In Validazione per Campioni, Monitoraggio Accettazione, Validato per IFRS9 | K40: + OP 556 impatti IFRS9
...

Sheet Catalogo Categorie Campi
A1: Entità DM Nome
A2: Nome Entità L2 | B2: ID_ENTITA_L2 | C2: Categoria Campo | D2: ID Categoria campo | E2: Descrizione Breve | F2: Note
A3: PRATICA | B3: IDL2_1 | C3: Tempo | D3: IDL2_1_1 | E3: Campi relativi alla storicizzazione, versionamento o loggatura
A4: PRATICA | B4: IDL2_1 | C4: Controparte | D4: IDL2_1_2 | E4: Informazioni e/o identificativi della/e controparti associate alla pratica
A5: PRATICA | B5: IDL2_1 | C5: Configurazione prodotto | D5: IDL2_1_3 | E5: Elenco di campi che utili alla configurazione del prodotto
A6: PRATICA | B6: IDL2_1 | C6: Attributo | D6: IDL2_1_4
A7: PRATICA | B7: IDL2_1 | C7: Stato pratica | D7: IDL2_1_5 | E7: Campi che tracciano lo stato della pratica
A8: PRATICA | B8: IDL2_1 | C8: Società Veicolo | D8: IDL2_1_6 | E8: Informazioni sulla società Veicolo della pratica
A9: PRATICA | B9: IDL2_1 | C9: Catena di Intermediazione | D9: IDL2_1_7 | E9: Campi riguardo la Catena di Intermediazione
A10: PRATICA | B10: IDL2_1 | C10: Date Pratica | D10: IDL2_1_8 | E10: Date associate alla pratica
A11: PRATICA | B11: IDL2_1 | C11: Score Pratica | D11: IDL2_1_9 | E11: Informazioni sugli score attribuiti alla pratica in fase di istruttoria
A12: PRATICA | B12: IDL2_1 | C12: Tassi e Rendimenti | D12: IDL2_1_10 | E12: Elenco dei tassi associati alla pratica
A13: PRATICA | B13: IDL2_1 | C13: Canale di acquisizione | D13: IDL2_1_11 | E13: Informazioni sul canale di acquisizione
A14: PRATICA | B14: IDL2_1 | C14: Utenti operatori pratica | D14: IDL2_1_12 | E14: Utenti che hanno apportato modifiche alla pratica nel suo processo
A15: PRATICA | B15: IDL2_1 | C15: Carta | D15: IDL2_1_14 | E15: Informazioni relative alla carta e al suo utilizzo
A16: PRATICA | B16: IDL2_1 | C16: Firme | D16: IDL2_1_15 | E16: Informazioni relative alla firma della pratica
A17: PRATICA | B17: IDL2_1 | C17: Flag | D17: IDL2_1_16 | E17: Flag associati alla pratica
A18: PRATICA | B18: IDL2_1 | C18: Importi Pratica | D18: IDL2_1_17 | E18: Elenco degli Importi Associati ad una pratica
A19: PRATICA | B19: IDL2_1 | C19: Pagamento | D19: IDL2_1_18 | E19: Informazioni relative ai pagamenti e ai metodi di pagamento
A20: PRATICA | B20: IDL2_1 | C20: Rate | D20: IDL2_1_19
A21: PRATICA | B21: IDL2_1 | C21: Conto corrente | D21: IDL2_1_20
A22: PRATICA | B22: IDL2_1 | C22: Parametri | D22: IDL2_1_21 | E22: Parametrizzazioni legate alla pratica
A23: PRATICA | B23: IDL2_1 | C23: Identificativo Auto | D23: IDL2_1_22 | E23: Infromazioni relative alle auto
A24: PRATICA | B24: IDL2_1 | C24: Cartolarizzazione | D24: IDL2_1_24
A25: CONTROPARTE | B25: IDL2_2 | C25: Identificativo Controparte | D25: IDL2_2_1 | E25: Identificativo/i univoco/i della controparte
A26: CONTROPARTE | B26: IDL2_2 | C26: Tempo | D26: IDL2_2_2 | E26: Campi relativi alla storicizzazione, versionamento o loggatura
A27: CONTROPARTE | B27: IDL2_2 | C27: Dati anagrafici personali | D27: IDL2_2_3 | E27: Dati anagrafici personali della controparte
A28: CONTROPARTE | B28: IDL2_2 | C28: Dati anagrafici non personali | D28: IDL2_2_3 | E28: Dati anagrafici non personali della controparte
A29: CONTROPARTE | B29: IDL2_2 | C29: Dati Residenza | D29: IDL2_2_4 | E29: Insieme di campi che identificano l'indirizzo di Residenza nel caso di persone fisiche
A30: CONTROPARTE | B30: IDL2_2 | C30: Dati Domicilio | D30: IDL2_2_5 | E30: Insieme di campi che identificano l'indirizzo di Domicilio nel caso di persone fisiche
A31: CONTROPARTE | B31: IDL2_2 | C31: Contatti | D31: IDL2_2_6 | E31: Insieme di campi con i contatti di riferimento
A32: CONTROPARTE | B32: IDL2_2 | C32: Dati Impiego | D32: IDL2_2_7 | E32: Dati sull'impiego lavorativo della controparte nel caso di persone fisiche
A33: SALDO_M | B33: IDL2_3 | C33: Identificativo pratica | D33: IDL2_3_1 | E33: Identificativo/i univoco/i della pratica alla quale il saldo in questione è associato
A34: SALDO_M | B34: IDL2_3 | C34: Tempo | D34: IDL2_3_2 | E34: Campi relativi alla storicizzazione, versionamento o loggatura
A35: SALDO_M | B35: IDL2_3 | C35: Identificativo saldo | D35: IDL2_3_3 | E35: Campi identificare la tipologia di saldo
A36: SALDO_M | B36: IDL2_3 | C36: Importi Saldo (Importi Saldo Contabile/Importi Saldo Gestionale) | D36: IDL2_3_4 | E36: Saldo (contabile e gestionale) e relative componenti, che avranno in base alla tipologia del saldo (se contabile o gestionale), diversa regola funzionale
... A47: CANALE ESITO | B47: IDL2_8 | C47: Canale Esito | D47: IDL2_8_3 | E47: Informazioni sulla classificazione in Web / Non Web del canale di Esito - "Atterraggio" della pratica
A48: PRATICA_M | B48: IDL2_10 | C48: Identificativo Pratica | D48: IDL2_10_1
A49: PRATICA_M | B49: IDL2_10 | C49: Tempo | D49: IDL2_10_2
A50: PRATICA_M | B50: IDL2_10 | C50: Controparti | D50: IDL2_10_3
...

Sheet DataQualityInterna
A2: Riga Campo | B2: Tutti Campi AT Valorizzati | C2: CAMPO DA SORGENTE NON MAIN vs CHIAVI DI AGGANCIO | D2: CAMPO DA SORGENTE NON MAIN, CAMPO CALCOLATO vs REGOLA TECNICA | E2: FORMATO ammesso
A3: PRATICA | B3: Per Utilizzare Cambiare l'Entità in cella A2 dal menù a tendina
A4: {=_xlfn.SEQUENCE(COUNTA(INDIRECT("'"&A3&"'!$B:$B"))-1) +2} -> 3 | B4: {=_xlfn.LET( _xlpm.AA, INDEX(INDIRECT("'"&A$3&"'!$1:$1048576"), ROW(), MATCH("FLAG_PK", INDIRECT("'"&A$3&"'!$2:$2"), 0)), _xlpm.BB, INDEX(INDIRECT("'"&A$3&"'!$1:$1048576"), ROW(), MATCH("FORMATO", INDIRECT("'"&A$3&"'!$2:$2"), 0)), _xlpm.CC, INDEX(INDIRECT("'"&A$3&"'!$1:$1048576"), ROW(), MATCH("LENGTH", INDIRECT("'"&A$3&"'!$2:$2"), 0)), _xlpm.DD, INDEX(INDIRECT("'"&A$3&"'!$1:$1048576"), ROW(), MATCH("DECIMAL", INDIRECT("'"&A$3&"'!$2:$2"), 0)), _xlpm.FF, INDEX(INDIRECT("'"&A$3&"'!$1:$1048576"), ROW(), MATCH("CAMPO CALCOLATO", INDIRECT("'"&A$3&"'!$2:$2"), 0)), _xlpm.GG, INDEX(INDIRECT("'"&A$3&"'!$1:$1048576"), ROW(), MATCH("CAMPO DA SORGENTE NON MAIN", INDIRECT("'"&A$3&"'!$2:$2"), 0)), _xlpm.HH, INDEX(INDIRECT("'"&A$3&"'!$1:$1048576"), ROW(), MATCH("REGOLA TECNICA", INDIRECT("'"&A$3&"'!$2:$2"), 0)), _xlpm.II, INDEX(INDIRECT("'"&A$3&"'!$1:$1048576"), ROW(), MATCH("CHIAVI DI AGGANCIO", INDIRECT("'"&A$3&"'!$2:$2"), 0)), _xlpm.LL, INDEX(INDIRECT("'"&A$3&"'!$1:$1048576"), ROW(), MATCH("DATI SENSIBILI", INDIRECT("'"&A$3&"'!$2:$2"), 0)), IF(_xlpm.AA="","❌ (FLAG_PK)", IF(_xlpm.BB="","❌ (FORMATO)", IF(_xlpm.CC="","❌ (LENGTH)", IF(_xlpm.DD="","❌ (DECIMAL)", IF(_xlpm.FF="","❌ (CAMPO CALCOLATO)", IF(_xlpm.GG="","❌ (CAMPO DA SORGENTE NON MAIN)", IF(_xlpm.HH="","❌ (REGOLA TECNICA)", IF(_xlpm.II="","❌ (CHIAVI DI AGGANCIO)", IF(_xlpm.LL="","❌ (DATI SENSIBILI)", "✅"))))))))) )} -> #N/A | C4: {=IF( INDEX(INDIRECT("'"&A$3&"'!$1:$1048576"), ROW(), MATCH("CAMPO DA SORGENTE NON MAIN", INDIRECT("'"&A$3&"'!$2:$2"), 0))="S", IF(INDEX(INDIRECT("'"&A$3&"'!$1:$1048576"), ROW(), MATCH("CHIAVI DI AGGANCIO", INDIRECT("'"&A$3&"'!$2:$2"), 0))="NA", "❌", "✅"), IF( INDEX(INDIRECT("'"&A$3&"'!$1:$1048576"), ROW(), MATCH("CAMPO DA SORGENTE NON MAIN", INDIRECT("'"&A$3&"'!$2:$2"), 0))="N", IF(INDEX(INDIRECT("'"&A$3&"'!$1:$1048576"), ROW(), MATCH("CHIAVI DI AGGANCIO", INDIRECT("'"&A$3&"'!$2:$2"), 0))<>"NA", "❌", "✅"), "⚠️" ) )} -> #N/A | D4: {=_xlfn.LET( _xlpm.CC, INDEX(INDIRECT("'"&A$3&"'!$1:$1048576"), ROW(), MATCH("CAMPO CALCOLATO", INDIRECT("'"&A$3&"'!$2:$2"), 0)), _xlpm.CDSM, INDEX(INDIRECT("'"&A$3&"'!$1:$1048576"), ROW(), MATCH("CAMPO DA SORGENTE NON MAIN", INDIRECT("'"&A$3&"'!$2:$2"), 0)), _xlpm.RT, INDEX(INDIRECT("'"&A$3&"'!$1:$1048576"), ROW(), MATCH("REGOLA TECNICA", INDIRECT("'"&A$3&"'!$2:$2"), 0)), IF(AND(OR(_xlpm.CC="S", _xlpm.CDSM="S"), OR(_xlpm.RT="NA", _xlpm.RT="")), "❌", IF(AND(_xlpm.CC="N", _xlpm.CDSM="N", _xlpm.RT<>"NA"), "❌", IF(AND(_xlpm.CC="N", _xlpm.CDSM="N"), "✅", IF(AND(OR(_xlpm.CC="S", _xlpm.CDSM="S"), _xlpm.RT<>"NA"), "✅", "⚠️")))) )} -> #N/A | E4: {=_xlfn.LET( _xlpm.CC, INDEX(INDIRECT("'"&A$3&"'!$1:$1048576"), ROW(), MATCH("FORMATO", INDIRECT("'"&A$3&"'!$2:$2"), 0)), IF(_xlpm.CC="NUMBER", "✅", IF(_xlpm.CC="DATE", "✅", IF(_xlpm.CC="VARCHAR", "✅", IF(_xlpm.CC="TIMESTAMP", "✅", "❌")))) )} -> #N/A
A5: 4 | B5: {=_xlfn.LET( _xlpm.AA, INDEX(INDIRECT("'"&A$3&"'!$1:$1048576"), ROW(), MATCH("FLAG_PK", INDIRECT("'"&A$3&"'!$2:$2"), 0)), _xlpm.BB, INDEX(INDIRECT("'"&A$3&"'!$1:$1048576"), ROW(), MATCH("FORMATO", INDIRECT("'"&A$3&"'!$2:$2"), 0)), _xlpm.CC, INDEX(INDIRECT("'"&A$3&"'!$1:$1048576"), ROW(), MATCH("LENGTH", INDIRECT("'"&A$3&"'!$2:$2"), 0)), _xlpm.DD, INDEX(INDIRECT("'"&A$3&"'!$1:$1048576"), ROW(), MATCH("DECIMAL", INDIRECT("'"&A$3&"'!$2:$2"), 0)), _xlpm.FF, INDEX(INDIRECT("'"&A$3&"'!$1:$1048576"), ROW(), MATCH("CAMPO CALCOLATO", INDIRECT("'"&A$3&"'!$2:$2"), 0)), _xlpm.GG, INDEX(INDIRECT("'"&A$3&"'!$1:$1048576"), ROW(), MATCH("CAMPO DA SORGENTE NON MAIN", INDIRECT("'"&A$3&"'!$2:$2"), 0)), _xlpm.HH, INDEX(INDIRECT("'"&A$3&"'!$1:$1048576"), ROW(), MATCH("REGOLA TECNICA", INDIRECT("'"&A$3&"'!$2:$2"), 0)), _xlpm.II, INDEX(INDIRECT("'"&A$3&"'!$1:$1048576"), ROW(), MATCH("CHIAVI DI AGGANCIO", INDIRECT("'"&A$3&"'!$2:$2"), 0)), _xlpm.LL, INDEX(INDIRECT("'"&A$3&"'!$1:$1048576"), ROW(), MATCH("DATI SENSIBILI", INDIRECT("'"&A$3&"'!$2:$2"), 0)), IF(_xlpm.AA="","❌ (FLAG_PK)", IF(_xlpm.BB="","❌ (FORMATO)", IF(_xlpm.CC="","❌ (LENGTH)", IF(_xlpm.DD="","❌ (DECIMAL)", IF(_xlpm.FF="","❌ (CAMPO CALCOLATO)", IF(_xlpm.GG="","❌ (CAMPO DA SORGENTE NON MAIN)", IF(_xlpm.HH="","❌ (REGOLA TECNICA)", IF(_xlpm.II="","❌ (CHIAVI DI AGGANCIO)", IF(_xlpm.LL="","❌ (DATI SENSIBILI)", "✅"))))))))) )} -> #N/A | C5: {=IF( INDEX(INDIRECT("'"&A$3&"'!$1:$1048576"), ROW(), MATCH("CAMPO DA SORGENTE NON MAIN", INDIRECT("'"&A$3&"'!$2:$2"), 0))="S", IF(INDEX(INDIRECT("'"&A$3&"'!$1:$1048576"), ROW(), MATCH("CHIAVI DI AGGANCIO", INDIRECT("'"&A$3&"'!$2:$2"), 0))="NA", "❌", "✅"), IF( INDEX(INDIRECT("'"&A$3&"'!$1:$1048576"), ROW(), MATCH("CAMPO DA SORGENTE NON MAIN", INDIRECT("'"&A$3&"'!$2:$2"), 0))="N", IF(INDEX(INDIRECT("'"&A$3&"'!$1:$1048576"), ROW(), MATCH("CHIAVI DI AGGANCIO", INDIRECT("'"&A$3&"'!$2:$2"), 0))<>"NA", "❌", "✅"), "⚠️" ) )} -> #N/A | D5: {=_xlfn.LET( _xlpm.CC, INDEX(INDIRECT("'"&A$3&"'!$1:$1048576"), ROW(), MATCH("CAMPO CALCOLATO", INDIRECT("'"&A$3&"'!$2:$2"), 0)), _xlpm.CDSM, INDEX(INDIRECT("'"&A$3&"'!$1:$1048576"), ROW(), MATCH("CAMPO DA SORGENTE NON MAIN", INDIRECT("'"&A$3&"'!$2:$2"), 0)), _xlpm.RT, INDEX(INDIRECT("'"&A$3&"'!$1:$1048576"), ROW(), MATCH("REGOLA TECNICA", INDIRECT("'"&A$3&"'!$2:$2"), 0)), IF(AND(OR(_xlpm.CC="S", _xlpm.CDSM="S"), OR(_xlpm.RT="NA", _xlpm.RT="")), "❌", IF(AND(_xlpm.CC="N", _xlpm.CDSM="N", _xlpm.RT<>"NA"), "❌", IF(AND(_xlpm.CC="N", _xlpm.CDSM="N"), "✅", IF(AND(OR(_xlpm.CC="S", _xlpm.CDSM="S"), _xlpm.RT<>"NA"), "✅", "⚠️")))) )} -> #N/A | E5: {=_xlfn.LET( _xlpm.CC, INDEX(INDIRECT("'"&A$3&"'!$1:$1048576"), ROW(), MATCH("FORMATO", INDIRECT("'"&A$3&"'!$2:$2"), 0)), IF(_xlpm.CC="NUMBER", "✅", IF(_xlpm.CC="DATE", "✅", IF(_xlpm.CC="VARCHAR", "✅", IF(_xlpm.CC="TIMESTAMP", "✅", "❌")))) )} -> #N/A
A6: 5 | B6: {=_xlfn.LET( _xlpm.AA, INDEX(INDIRECT("'"&A$3&"'!$1:$1048576"), ROW(), MATCH("FLAG_PK", INDIRECT("'"&A$3&"'!$2:$2"), 0)), _xlpm.BB, INDEX(INDIRECT("'"&A$3&"'!$1:$1048576"), ROW(), MATCH("FORMATO", INDIRECT("'"&A$3&"'!$2:$2"), 0)), _xlpm.CC, INDEX(INDIRECT("'"&A$3&"'!$1:$1048576"), ROW(), MATCH("LENGTH", INDIRECT("'"&A$3&"'!$2:$2"), 0)), _xlpm.DD, INDEX(INDIRECT("'"&A$3&"'!$1:$1048576"), ROW(), MATCH("DECIMAL", INDIRECT("'"&A$3&"'!$2:$2"), 0)), _xlpm.FF, INDEX(INDIRECT("'"&A$3&"'!$1:$1048576"), ROW(), MATCH("CAMPO CALCOLATO", INDIRECT("'"&A$3&"'!$2:$2"), 0)), _xlpm.GG, INDEX(INDIRECT("'"&A$3&"'!$1:$1048576"), ROW(), MATCH("CAMPO DA SORGENTE NON MAIN", INDIRECT("'"&A$3&"'!$2:$2"), 0)), _xlpm.HH, INDEX(INDIRECT("'"&A$3&"'!$1:$1048576"), ROW(), MATCH("REGOLA TECNICA", INDIRECT("'"&A$3&"'!$2:$2"), 0)), _xlpm.II, INDEX(INDIRECT("'"&A$3&"'!$1:$1048576"), ROW(), MATCH("CHIAVI DI AGGANCIO", INDIRECT("'"&A$3&"'!$2:$2"), 0)), _xlpm.LL, INDEX(INDIRECT("'"&A$3&"'!$1:$1048576"), ROW(), MATCH("DATI SENSIBILI", INDIRECT("'"&A$3&"'!$2:$2"), 0)), IF(_xlpm.AA="","❌ (FLAG_PK)", IF(_xlpm.BB="","❌ (FORMATO)", IF(_xlpm.CC="","❌ (LENGTH)", IF(_xlpm.DD="","❌ (DECIMAL)", IF(_xlpm.FF="","❌ (CAMPO CALCOLATO)", IF(_xlpm.GG="","❌ (CAMPO DA SORGENTE NON MAIN)", IF(_xlpm.HH="","❌ (REGOLA TECNICA)", IF(_xlpm.II="","❌ (CHIAVI DI AGGANCIO)", IF(_xlpm.LL="","❌ (DATI SENSIBILI)", "✅"))))))))) )} -> #N/A | C6: {=IF( INDEX(INDIRECT("'"&A$3&"'!$1:$1048576"), ROW(), MATCH("CAMPO DA SORGENTE NON MAIN", INDIRECT("'"&A$3&"'!$2:$2"), 0))="S", IF(INDEX(INDIRECT("'"&A$3&"'!$1:$1048576"), ROW(), MATCH("CHIAVI DI AGGANCIO", INDIRECT("'"&A$3&"'!$2:$2"), 0))="NA", "❌", "✅"), IF( INDEX(INDIRECT("'"&A$3&"'!$1:$1048576"), ROW(), MATCH("CAMPO DA SORGENTE NON MAIN", INDIRECT("'"&A$3&"'!$2:$2"), 0))="N", IF(INDEX(INDIRECT("'"&A$3&"'!$1:$1048576"), ROW(), MATCH("CHIAVI DI AGGANCIO", INDIRECT("'"&A$3&"'!$2:$2"), 0))<>"NA", "❌", "✅"), "⚠️" ) )} -> #N/A | D6: {=_xlfn.LET( _xlpm.CC, INDEX(INDIRECT("'"&A$3&"'!$1:$1048576"), ROW(), MATCH("CAMPO CALCOLATO", INDIRECT("'"&A$3&"'!$2:$2"), 0)), _xlpm.CDSM, INDEX(INDIRECT("'"&A$3&"'!$1:$1048576"), ROW(), MATCH("CAMPO DA SORGENTE NON MAIN", INDIRECT("'"&A$3&"'!$2:$2"), 0)), _xlpm.RT, INDEX(INDIRECT("'"&A$3&"'!$1:$1048576"), ROW(), MATCH("REGOLA TECNICA", INDIRECT("'"&A$3&"'!$2:$2"), 0)), IF(AND(OR(_xlpm.CC="S", _xlpm.CDSM="S"), OR(_xlpm.RT="NA", _xlpm.RT="")), "❌", IF(AND(_xlpm.CC="N", _xlpm.CDSM="N", _xlpm.RT<>"NA"), "❌", IF(AND(_xlpm.CC="N", _xlpm.CDSM="N"), "✅", IF(AND(OR(_xlpm.CC="S", _xlpm.CDSM="S"), _xlpm.RT<>"NA"), "✅", "⚠️")))) )} -> #N/A | E6: {=_xlfn.LET( _xlpm.CC, INDEX(INDIRECT("'"&A$3&"'!$1:$1048576"), ROW(), MATCH("FORMATO", INDIRECT("'"&A$3&"'!$2:$2"), 0)), IF(_xlpm.CC="NUMBER", "✅", IF(_xlpm.CC="DATE", "✅", IF(_xlpm.CC="VARCHAR", "✅", IF(_xlpm.CC="TIMESTAMP", "✅", "❌")))) )} -> #N/A
A7: 6 | B7: {=_xlfn.LET( _xlpm.AA, INDEX(INDIRECT("'"&A$3&"'!$1:$1048576"), ROW(), MATCH("FLAG_PK", INDIRECT("'"&A$3&"'!$2:$2"), 0)), _xlpm.BB, INDEX(INDIRECT("'"&A$3&"'!$1:$1048576"), ROW(), MATCH("FORMATO", INDIRECT("'"&A$3&"'!$2:$2"), 0)), _xlpm.CC, INDEX(INDIRECT("'"&A$3&"'!$1:$1048576"), ROW(), MATCH("LENGTH", INDIRECT("'"&A$3&"'!$2:$2"), 0)), _xlpm.DD, INDEX(INDIRECT("'"&A$3&"'!$1:$1048576"), ROW(), MATCH("DECIMAL", INDIRECT("'"&A$3&"'!$2:$2"), 0)), _xlpm.FF, INDEX(INDIRECT("'"&A$3&"'!$1:$1048576"), ROW(), MATCH("CAMPO CALCOLATO", INDIRECT("'"&A$3&"'!$2:$2"), 0)), _xlpm.GG, INDEX(INDIRECT("'"&A$3&"'!$1:$1048576"), ROW(), MATCH("CAMPO DA SORGENTE NON MAIN", INDIRECT("'"&A$3&"'!$2:$2"), 0)), _xlpm.HH, INDEX(INDIRECT("'"&A$3&"'!$1:$1048576"), ROW(), MATCH("REGOLA TECNICA", INDIRECT("'"&A$3&"'!$2:$2"), 0)), _xlpm.II, INDEX(INDIRECT("'"&A$3&"'!$1:$1048576"), ROW(), MATCH("CHIAVI DI AGGANCIO", INDIRECT("'"&A$3&"'!$2:$2"), 0)), _xlpm.LL, INDEX(INDIRECT("'"&A$3&"'!$1:$1048576"), ROW(), MATCH("DATI SENSIBILI", INDIRECT("'"&A$3&"'!$2:$2"), 0)), IF(_xlpm.AA="","❌ (FLAG_PK)", IF(_xlpm.BB="","❌ (FORMATO)", IF(_xlpm.CC="","❌ (LENGTH)", IF(_xlpm.DD="","❌ (DECIMAL)", IF(_xlpm.FF="","❌ (CAMPO CALCOLATO)", IF(_xlpm.GG="","❌ (CAMPO DA SORGENTE NON MAIN)", IF(_xlpm.HH="","❌ (REGOLA TECNICA)", IF(_xlpm.II="","❌ (CHIAVI DI AGGANCIO)", IF(_xlpm.LL="","❌ (DATI SENSIBILI)", "✅"))))))))) )} -> #N/A | C7: {=IF( INDEX(INDIRECT("'"&A$3&"'!$1:$1048576"), ROW(), MATCH("CAMPO DA SORGENTE NON MAIN", INDIRECT("'"&A$3&"'!$2:$2"), 0))="S", IF(INDEX(INDIRECT("'"&A$3&"'!$1:$1048576"), ROW(), MATCH("CHIAVI DI AGGANCIO", INDIRECT("'"&A$3&"'!$2:$2"), 0))="NA", "❌", "✅"), IF( INDEX(INDIRECT("'"&A$3&"'!$1:$1048576"), ROW(), MATCH("CAMPO DA SORGENTE NON MAIN", INDIRECT("'"&A$3&"'!$2:$2"), 0))="N", IF(INDEX(INDIRECT("'"&A$3&"'!$1:$1048576"), ROW(), MATCH("CHIAVI DI AGGANCIO", INDIRECT("'"&A$3&"'!$2:$2"), 0))<>"NA", "❌", "✅"), "⚠️" ) )} -> #N/A | D7: {=_xlfn.LET( _xlpm.CC, INDEX(INDIRECT("'"&A$3&"'!$1:$1048576"), ROW(), MATCH("CAMPO CALCOLATO", INDIRECT("'"&A$3&"'!$2:$2"), 0)), _xlpm.CDSM, INDEX(INDIRECT("'"&A$3&"'!$1:$1048576"), ROW(), MATCH("CAMPO DA SORGENTE NON MAIN", INDIRECT("'"&A$3&"'!$2:$2"), 0)), _xlpm.RT, INDEX(INDIRECT("'"&A$3&"'!$1:$1048576"), ROW(), MATCH("REGOLA TECNICA", INDIRECT("'"&A$3&"'!$2:$2"), 0)), IF(AND(OR(_xlpm.CC="S", _xlpm.CDSM="S"), OR(_xlpm.RT="NA", _xlpm.RT="")), "❌", IF(AND(_xlpm.CC="N", _xlpm.CDSM="N", _xlpm.RT<>"NA"), "❌", IF(AND(_xlpm.CC="N", _xlpm.CDSM="N"), "✅", IF(AND(OR(_xlpm.CC="S", _xlpm.CDSM="S"), _xlpm.RT<>"NA"), "✅", "⚠️")))) )} -> #N/A | E7: {=_xlfn.LET( _xlpm.CC, INDEX(INDIRECT("'"&A$3&"'!$1:$1048576"), ROW(), MATCH("FORMATO", INDIRECT("'"&A$3&"'!$2:$2"), 0)), IF(_xlpm.CC="NUMBER", "✅", IF(_xlpm.CC="DATE", "✅", IF(_xlpm.CC="VARCHAR", "✅", IF(_xlpm.CC="TIMESTAMP", "✅", "❌")))) )} -> #N/A
A8: 7 | B8: {=_xlfn.LET( _xlpm.AA, INDEX(INDIRECT("'"&A$3&"'!$1:$1048576"), ROW(), MATCH("FLAG_PK", INDIRECT("'"&A$3&"'!$2:$2"), 0)), _xlpm.BB, INDEX(INDIRECT("'"&A$3&"'!$1:$1048576"), ROW(), MATCH("FORMATO", INDIRECT("'"&A$3&"'!$2:$2"), 0)), _xlpm.CC, INDEX(INDIRECT("'"&A$3&"'!$1:$1048576"), ROW(), MATCH("LENGTH", INDIRECT("'"&A$3&"'!$2:$2"), 0)), _xlpm.DD, INDEX(INDIRECT("'"&A$3&"'!$1:$1048576"), ROW(), MATCH("DECIMAL", INDIRECT("'"&A$3&"'!$2:$2"), 0)), _xlpm.FF, INDEX(INDIRECT("'"&A$3&"'!$1:$1048576"), ROW(), MATCH("CAMPO CALCOLATO", INDIRECT("'"&A$3&"'!$2:$2"), 0)), _xlpm.GG, INDEX(INDIRECT("'"&A$3&"'!$1:$1048576"), ROW(), MATCH("CAMPO DA SORGENTE NON MAIN", INDIRECT("'"&A$3&"'!$2:$2"), 0)), _xlpm.HH, INDEX(INDIRECT("'"&A$3&"'!$1:$1048576"), ROW(), MATCH("REGOLA TECNICA", INDIRECT("'"&A$3&"'!$2:$2"), 0)), _xlpm.II, INDEX(INDIRECT("'"&A$3&"'!$1:$1048576"), ROW(), MATCH("CHIAVI DI AGGANCIO", INDIRECT("'"&A$3&"'!$2:$2"), 0)), _xlpm.LL, INDEX(INDIRECT("'"&A$3&"'!$1:$1048576"), ROW(), MATCH("DATI SENSIBILI", INDIRECT("'"&A$3&"'!$2:$2"), 0)), IF(_xlpm.AA="","❌ (FLAG_PK)", IF(_xlpm.BB="","❌ (FORMATO)", IF(_xlpm.CC="","❌ (LENGTH)", IF(_xlpm.DD="","❌ (DECIMAL)", IF(_xlpm.FF="","❌ (CAMPO CALCOLATO)", IF(_xlpm.GG="","❌ (CAMPO DA SORGENTE NON MAIN)", IF(_xlpm.HH="","❌ (REGOLA TECNICA)", IF(_xlpm.II="","❌ (CHIAVI DI AGGANCIO)", IF(_xlpm.LL="","❌ (DATI SENSIBILI)", "✅"))))))))) )} -> #N/A | C8: {=IF( INDEX(INDIRECT("'"&A$3&"'!$1:$1048576"), ROW(), MATCH("CAMPO DA SORGENTE NON MAIN", INDIRECT("'"&A$3&"'!$2:$2"), 0))="S", IF(INDEX(INDIRECT("'"&A$3&"'!$1:$1048576"), ROW(), MATCH("CHIAVI DI AGGANCIO", INDIRECT("'"&A$3&"'!$2:$2"), 0))="NA", "❌", "✅"), IF( INDEX(INDIRECT("'"&A$3&"'!$1:$1048576"), ROW(), MATCH("CAMPO DA SORGENTE NON MAIN", INDIRECT("'"&A$3&"'!$2:$2"), 0))="N", IF(INDEX(INDIRECT("'"&A$3&"'!$1:$1048576"), ROW(), MATCH("CHIAVI DI AGGANCIO", INDIRECT("'"&A$3&"'!$2:$2"), 0))<>"NA", "❌", "✅"), "⚠️" ) )} -> #N/A | D8: {=_xlfn.LET( _xlpm.CC, INDEX(INDIRECT("'"&A$3&"'!$1:$1048576"), ROW(), MATCH("CAMPO CALCOLATO", INDIRECT("'"&A$3&"'!$2:$2"), 0)), _xlpm.CDSM, INDEX(INDIRECT("'"&A$3&"'!$1:$1048576"), ROW(), MATCH("CAMPO DA SORGENTE NON MAIN", INDIRECT("'"&A$3&"'!$2:$2"), 0)), _xlpm.RT, INDEX(INDIRECT("'"&A$3&"'!$1:$1048576"), ROW(), MATCH("REGOLA TECNICA", INDIRECT("'"&A$3&"'!$2:$2"), 0)), IF(AND(OR(_xlpm.CC="S", _xlpm.CDSM="S"), OR(_xlpm.RT="NA", _xlpm.RT="")), "❌", IF(AND(_xlpm.CC="N", _xlpm.CDSM="N", _xlpm.RT<>"NA"), "❌", IF(AND(_xlpm.CC="N", _xlpm.CDSM="N"), "✅", IF(AND(OR(_xlpm.CC="S", _xlpm.CDSM="S"), _xlpm.RT<>"NA"), "✅", "⚠️")))) )} -> #N/A | E8: {=_xlfn.LET( _xlpm.CC, INDEX(INDIRECT("'"&A$3&"'!$1:$1048576"), ROW(), MATCH("FORMATO", INDIRECT("'"&A$3&"'!$2:$2"), 0)), IF(_xlpm.CC="NUMBER", "✅", IF(_xlpm.CC="DATE", "✅", IF(_xlpm.CC="VARCHAR", "✅", IF(_xlpm.CC="TIMESTAMP", "✅", "❌")))) )} -> #N/A
A9: 8 | B9: {=_xlfn.LET( _xlpm.AA, INDEX(INDIRECT("'"&A$3&"'!$1:$1048576"), ROW(), MATCH("FLAG_PK", INDIRECT("'"&A$3&"'!$2:$2"), 0)), _xlpm.BB, INDEX(INDIRECT("'"&A$3&"'!$1:$1048576"), ROW(), MATCH("FORMATO", INDIRECT("'"&A$3&"'!$2:$2"), 0)), _xlpm.CC, INDEX(INDIRECT("'"&A$3&"'!$1:$1048576"), ROW(), MATCH("LENGTH", INDIRECT("'"&A$3&"'!$2:$2"), 0)), _xlpm.DD, INDEX(INDIRECT("'"&A$3&"'!$1:$1048576"), ROW(), MATCH("DECIMAL", INDIRECT("'"&A$3&"'!$2:$2"), 0)), _xlpm.FF, INDEX(INDIRECT("'"&A$3&"'!$1:$1048576"), ROW(), MATCH("CAMPO CALCOLATO", INDIRECT("'"&A$3&"'!$2:$2"), 0)), _xlpm.GG, INDEX(INDIRECT("'"&A$3&"'!$1:$1048576"), ROW(), MATCH("CAMPO DA SORGENTE NON MAIN", INDIRECT("'"&A$3&"'!$2:$2"), 0)), _xlpm.HH, INDEX(INDIRECT("'"&A$3&"'!$1:$1048576"), ROW(), MATCH("REGOLA TECNICA", INDIRECT("'"&A$3&"'!$2:$2"), 0)), _xlpm.II, INDEX(INDIRECT("'"&A$3&"'!$1:$1048576"), ROW(), MATCH("CHIAVI DI AGGANCIO", INDIRECT("'"&A$3&"'!$2:$2"), 0)), _xlpm.LL, INDEX(INDIRECT("'"&A$3&"'!$1:$1048576"), ROW(), MATCH("DATI SENSIBILI", INDIRECT("'"&A$3&"'!$2:$2"), 0)), IF(_xlpm.AA="","❌ (FLAG_PK)", IF(_xlpm.BB="","❌ (FORMATO)", IF(_xlpm.CC="","❌ (LENGTH)", IF(_xlpm.DD="","❌ (DECIMAL)", IF(_xlpm.FF="","❌ (CAMPO CALCOLATO)", IF(_xlpm.GG="","❌ (CAMPO DA SORGENTE NON MAIN)", IF(_xlpm.HH="","❌ (REGOLA TECNICA)", IF(_xlpm.II="","❌ (CHIAVI DI AGGANCIO)", IF(_xlpm.LL="","❌ (DATI SENSIBILI)", "✅"))))))))) )} -> #N/A | C9: {=IF( INDEX(INDIRECT("'"&A$3&"'!$1:$1048576"), ROW(), MATCH("CAMPO DA SORGENTE NON MAIN", INDIRECT("'"&A$3&"'!$2:$2"), 0))="S", IF(INDEX(INDIRECT("'"&A$3&"'!$1:$1048576"), ROW(), MATCH("CHIAVI DI AGGANCIO", INDIRECT("'"&A$3&"'!$2:$2"), 0))="NA", "❌", "✅"), IF( INDEX(INDIRECT("'"&A$3&"'!$1:$1048576"), ROW(), MATCH("CAMPO DA SORGENTE NON MAIN", INDIRECT("'"&A$3&"'!$2:$2"), 0))="N", IF(INDEX(INDIRECT("'"&A$3&"'!$1:$1048576"), ROW(), MATCH("CHIAVI DI AGGANCIO", INDIRECT("'"&A$3&"'!$2:$2"), 0))<>"NA", "❌", "✅"), "⚠️" ) )} -> #N/A | D9: {=_xlfn.LET( _xlpm.CC, INDEX(INDIRECT("'"&A$3&"'!$1:$1048576"), ROW(), MATCH("CAMPO CALCOLATO", INDIRECT("'"&A$3&"'!$2:$2"), 0)), _xlpm.CDSM, INDEX(INDIRECT("'"&A$3&"'!$1:$1048576"), ROW(), MATCH("CAMPO DA SORGENTE NON MAIN", INDIRECT("'"&A$3&"'!$2:$2"), 0)), _xlpm.RT, INDEX(INDIRECT("'"&A$3&"'!$1:$1048576"), ROW(), MATCH("REGOLA TECNICA", INDIRECT("'"&A$3&"'!$2:$2"), 0)), IF(AND(OR(_xlpm.CC="S", _xlpm.CDSM="S"), OR(_xlpm.RT="NA", _xlpm.RT="")), "❌", IF(AND(_xlpm.CC="N", _xlpm.CDSM="N", _xlpm.RT<>"NA"), "❌", IF(AND(_xlpm.CC="N", _xlpm.CDSM="N"), "✅", IF(AND(OR(_xlpm.CC="S", _xlpm.CDSM="S"), _xlpm.RT<>"NA"), "✅", "⚠️")))) )} -> #N/A | E9: {=_xlfn.LET( _xlpm.CC, INDEX(INDIRECT("'"&A$3&"'!$1:$1048576"), ROW(), MATCH("FORMATO", INDIRECT("'"&A$3&"'!$2:$2"), 0)), IF(_xlpm.CC="NUMBER", "✅", IF(_xlpm.CC="DATE", "✅", IF(_xlpm.CC="VARCHAR", "✅", IF(_xlpm.CC="TIMESTAMP", "✅", "❌")))) )} -> #N/A
